<?xml version="1.0"?>
<robot xmlns:xacro="http://www.ros.org/wiki/xacro" name="robot">

    <xacro:include filename= "lidar.xacro"/>
        
  <material name="green_dark">
    <color rgba="0.0 0.5 0.0 1"/>
  </material>

  <material name="blue">
      <color rgba="0.0 0.0 1.0 1"/>
  </material>

  <material name="yellow">
      <color rgba="1.0 1.0 0.0 1"/>
  </material>

  <material name="white">
      <color rgba="1.0 1.0 1.0 1"/>
  </material>

  <material name="box_bot_blue">
      <color rgba="0.088656 0.428691 0.491021 1"/>
  </material>

  <link name="base_link">
  </link>


  <!-- Body -->
  <link name="chassis">
     <visual>
        <geometry>
          <box size="0.1 0.075 0.03"/>
        </geometry>
        <material name="box_bot_blue"/>
     </visual>
     
  

  <inertial>
    <mass value="0.2"/>
    <origin rpy="0 0 0" xyz="0 0 0"/>
    <inertia ixx= "0.00010875"  ixy= "0" ixz= "0" iyy= "0.0001816666666666667" iyz= "0" izz= "0.0001816666666666667" />
  </inertial>

  <collision>
    <geometry>
      <box size="0.1 0.075 0.03"/>
    </geometry>
  </collision>
</link>
  <gazebo reference="chassis">
      <material>Gazebo/Blue</material>
  </gazebo>

  <joint name="base_link_joint" type="fixed">
    <origin rpy="0 0 0" xyz="0 0 0.03" />
    <parent link="base_link" />
    <child link="chassis" />
  </joint>

  <!-- Wheel Left -->
  <link name="left_front_wheel">      
      <visual>
        <origin rpy="0 0 0" xyz="0 0 -0.005"/>
        <geometry>
          <cylinder length="0.01" radius="0.015"/>
        </geometry>
        <material name="white"/>
      </visual>


    <collision>
      <origin rpy="0 0 0" xyz="0 0 0"/>
      <geometry>
        <cylinder length="0.01" radius="0.015"/>
      </geometry>
    </collision>

    <inertial>
      <origin rpy="0 0 0" xyz="0 0 0"/>
      <mass value="0.05"/>
      <inertia ixx= "2.8166666666666667e-06"  ixy= "0" ixz= "0" iyy= "2.8166666666666667e-06" iyz= "0" izz= "5.625e-06" />
    </inertial>

  </link>

   <gazebo reference="left_front_wheel">
    <kp>1000000.0</kp>
    <kd>1000000.0</kd>
    <mu1>10.0</mu1>
    <mu2>10.0</mu2>
    <material>Gazebo/Red</material>
  </gazebo>

  <joint name="joint_left_front_wheel" type="continuous">
    <origin rpy="1.5707 0 0" xyz="0.025 0.038 -0.015"/>
    <child link="left_front_wheel"/>
    <parent link="chassis"/>
    <axis rpy="0 0 0" xyz="0 0 1"/>
    <limit effort="10000" velocity="1000"/>
    <joint_properties damping="1.0" friction="1.0"/>
  </joint>

  <!-- Wheel Left -->
  <link name="left_back_wheel">      
      <visual>
        <origin rpy="0 0 0" xyz="0 0 -0.005"/>
        <geometry>
          <cylinder length="0.01" radius="0.015"/>
        </geometry>
        <material name="white"/>
      </visual>


    <collision>
      <origin rpy="0 0 0" xyz="0 0 0"/>
      <geometry>
        <cylinder length="0.01" radius="0.015"/>
      </geometry>
    </collision>

    <inertial>
      <origin rpy="0 0 0" xyz="0 0 0"/>
      <mass value="0.05"/>
      <inertia ixx= "2.8166666666666667e-06"  ixy= "0" ixz= "0" iyy= "2.8166666666666667e-06" iyz= "0" izz= "5.625e-06" />
    </inertial>

  </link>
   <gazebo reference="left_back_wheel">
    <kp>1000000.0</kp>
    <kd>1000000.0</kd>
    <mu1>10.0</mu1>
    <mu2>10.0</mu2>
    <material>Gazebo/Red</material>
  </gazebo>

  <joint name="joint_left_back_wheel" type="continuous">
    <origin rpy="1.5707 0 0" xyz="-0.025 0.038 -0.015"/>
    <child link="left_back_wheel"/>
    <parent link="chassis"/>
    <axis rpy="0 0 0" xyz="0 0 1"/>
    <limit effort="10000" velocity="1000"/>
    <joint_properties damping="1.0" friction="1.0"/>
  </joint>

  <!-- Wheel Right -->
  <link name="right_front_wheel">      
      <visual>
        <origin rpy="0 0 0" xyz="0 0 0.005"/>
        <geometry>
          <cylinder length="0.01" radius="0.015"/>
        </geometry>
        <material name="white"/>
      </visual>
      <collision>
        <origin rpy="0 0 0" xyz="0 0 0"/>
        <geometry>
          <cylinder length="0.01" radius="0.015"/>
        </geometry>
      </collision>

      <inertial>
        <origin rpy="0 0 0" xyz="0 0 0"/>
        <mass value="0.05"/>
        <inertia ixx= "2.8166666666666667e-06"  ixy= "0" ixz= "0" iyy= "2.8166666666666667e-06" iyz= "0" izz= "5.625e-06" />
      </inertial>
  </link>
  <gazebo reference="right_front_wheel">
    <kp>1000000.0</kp>
    <kd>1000000.0</kd>
    <mu1>10.0</mu1>
    <mu2>10.0</mu2>
    <material>Gazebo/Red</material>
  </gazebo>
  <joint name="joint_right_front_wheel" type="continuous">  
    <origin rpy="1.5707 0 0" xyz="0.025 -0.038 -0.015"/>
    <child link="right_front_wheel"/>
    <parent link="chassis"/>
    <axis rpy="0 0 0" xyz="0 0 1"/>
    <limit effort="10000" velocity="1000"/>
    <joint_properties damping="1.0" friction="1.0"/>
  </joint>

<!-- Wheel Right -->
  <link name="right_back_wheel">      
      <visual>
        <origin rpy="0 0 0" xyz="0 0 0.005"/>
        <geometry>
          <cylinder length="0.01" radius="0.015"/>
        </geometry>
        <material name="white"/>
      </visual>
      <collision>
        <origin rpy="0 0 0" xyz="0 0 0"/>
        <geometry>
          <cylinder length="0.01" radius="0.015"/>
        </geometry>
      </collision>

      <inertial>
        <origin rpy="0 0 0" xyz="0 0 0"/>
        <mass value="0.05"/>
        <inertia ixx= "2.8166666666666667e-06"  ixy= "0" ixz= "0" iyy= "2.8166666666666667e-06" iyz= "0" izz= "5.625e-06" />
      </inertial>
  </link>
  <gazebo reference="right_back_wheel">
    <kp>1000000.0</kp>
    <kd>1000000.0</kd>
    <mu1>10.0</mu1>
    <mu2>10.0</mu2>
    <material>Gazebo/Red</material>
  </gazebo>

  <joint name="joint_right_back_wheel" type="continuous">  
    <origin rpy="1.5707 0 0" xyz="-0.025 -0.038 -0.015"/>
    <child link="right_back_wheel"/>
    <parent link="chassis"/>
    <axis rpy="0 0 0" xyz="0 0 1"/>
    <limit effort="10000" velocity="1000"/>
    <joint_properties damping="1.0" friction="1.0"/>
  </joint>

 <!-- JOINT PUBLISHER -->
  <gazebo>
    <plugin name="box_bot_joint_state" filename="libgazebo_ros_joint_state_publisher.so">
      <ros>
          <remapping>~/out:=joint_states</remapping>
      </ros>
      <update_rate>30</update_rate>

      <joint_name>joint_left_front_wheel</joint_name>
      <joint_name>joint_left_back_wheel</joint_name>
      <joint_name>joint_right_front_wheel</joint_name>
      <joint_name>joint_right_back_wheel</joint_name>

      
    </plugin>
  </gazebo>

  <!-- Differential drive -->
  <gazebo>
    <plugin filename="libgazebo_ros_diff_drive.so" name="differential_drive_controller">

      <!-- wheels -->
      <left_joint>joint_left_back_wheel</left_joint>
      <right_joint>joint_right_back_wheel</right_joint>

      <!-- kinematics -->
      <wheel_separation>0.075</wheel_separation>
      <wheel_diameter>0.03</wheel_diameter>

      <!-- limits -->
      <max_wheel_torque>1.0</max_wheel_torque>
      <max_wheel_acceleration>0.5</max_wheel_acceleration>

      <!-- output -->
      <publish_odom>true</publish_odom>
      <publish_odom_tf>true</publish_odom_tf>

      <odometry_frame>odom</odometry_frame>
      <robot_base_frame>base_link</robot_base_frame>

    </plugin>
  </gazebo>
</robot>